Traceback (most recent call last):
  File "the-raise-and-assert-statements.py", line 18, in <module>
    raise Exception('This is the error message.')
Exception: This is the error message.
Traceback (most recent call last):
  File "the-raise-and-assert-statements.py", line 18, in <module>
    raise Exception('This is the error message.')
Exception: This is the error message.
